Traceback (most recent call last):
  File "/Users/elmer/opt/anaconda3/envs/jupyter-book/lib/python3.13/site-packages/jupyter_cache/executors/utils.py", line 58, in single_nb_execution
    executenb(
    ~~~~~~~~~^
        nb,
        ^^^
    ...<4 lines>...
        **kwargs,
        ^^^^^^^^^
    )
    ^
  File "/Users/elmer/opt/anaconda3/envs/jupyter-book/lib/python3.13/site-packages/nbclient/client.py", line 1319, in execute
    return NotebookClient(nb=nb, resources=resources, km=km, **kwargs).execute()
           ~~~~~~~~~~~~~~~~~~~~~~~~~~~~~~~~~~~~~~~~~~~~~~~~~~~~~~~~~~~~~~~~~~~^^
  File "/Users/elmer/opt/anaconda3/envs/jupyter-book/lib/python3.13/site-packages/jupyter_core/utils/__init__.py", line 165, in wrapped
    return loop.run_until_complete(inner)
           ~~~~~~~~~~~~~~~~~~~~~~~^^^^^^^
  File "/Users/elmer/opt/anaconda3/envs/jupyter-book/lib/python3.13/asyncio/base_events.py", line 719, in run_until_complete
    return future.result()
           ~~~~~~~~~~~~~^^
  File "/Users/elmer/opt/anaconda3/envs/jupyter-book/lib/python3.13/site-packages/nbclient/client.py", line 709, in async_execute
    await self.async_execute_cell(
        cell, index, execution_count=self.code_cells_executed + 1
    )
  File "/Users/elmer/opt/anaconda3/envs/jupyter-book/lib/python3.13/site-packages/nbclient/client.py", line 1062, in async_execute_cell
    await self._check_raise_for_error(cell, cell_index, exec_reply)
  File "/Users/elmer/opt/anaconda3/envs/jupyter-book/lib/python3.13/site-packages/nbclient/client.py", line 918, in _check_raise_for_error
    raise CellExecutionError.from_cell_and_msg(cell, exec_reply_content)
nbclient.exceptions.CellExecutionError: An error occurred while executing the following cell:
------------------
# Make a copy of the dataframe with only selected columns -and- rename some columns
columns = ['Name','City','Height (m)', 'Birth Year']
df2 = df[columns].copy().rename(columns={'Birth Year':'Year','Height (m)':'Height'})
df2
------------------


[31m---------------------------------------------------------------------------[39m
[31mKeyError[39m                                  Traceback (most recent call last)
[36mCell[39m[36m [39m[32mIn[35][39m[32m, line 3[39m
[32m      1[39m [38;5;66;03m# Make a copy of the dataframe with only selected columns -and- rename some columns[39;00m
[32m      2[39m columns = [[33m'[39m[33mName[39m[33m'[39m,[33m'[39m[33mCity[39m[33m'[39m,[33m'[39m[33mHeight (m)[39m[33m'[39m, [33m'[39m[33mBirth Year[39m[33m'[39m]
[32m----> [39m[32m3[39m df2 = [43mdf[49m[43m[[49m[43mcolumns[49m[43m][49m.copy().rename(columns={[33m'[39m[33mBirth Year[39m[33m'[39m:[33m'[39m[33mYear[39m[33m'[39m,[33m'[39m[33mHeight (m)[39m[33m'[39m:[33m'[39m[33mHeight[39m[33m'[39m})
[32m      4[39m df2

[36mFile [39m[32m~/opt/anaconda3/envs/jupyter-book/lib/python3.13/site-packages/pandas/core/frame.py:4113[39m, in [36mDataFrame.__getitem__[39m[34m(self, key)[39m
[32m   4111[39m     [38;5;28;01mif[39;00m is_iterator(key):
[32m   4112[39m         key = [38;5;28mlist[39m(key)
[32m-> [39m[32m4113[39m     indexer = [38;5;28;43mself[39;49m[43m.[49m[43mcolumns[49m[43m.[49m[43m_get_indexer_strict[49m[43m([49m[43mkey[49m[43m,[49m[43m [49m[33;43m"[39;49m[33;43mcolumns[39;49m[33;43m"[39;49m[43m)[49m[[32m1[39m]
[32m   4115[39m [38;5;66;03m# take() does not accept boolean indexers[39;00m
[32m   4116[39m [38;5;28;01mif[39;00m [38;5;28mgetattr[39m(indexer, [33m"[39m[33mdtype[39m[33m"[39m, [38;5;28;01mNone[39;00m) == [38;5;28mbool[39m:

[36mFile [39m[32m~/opt/anaconda3/envs/jupyter-book/lib/python3.13/site-packages/pandas/core/indexes/base.py:6212[39m, in [36mIndex._get_indexer_strict[39m[34m(self, key, axis_name)[39m
[32m   6209[39m [38;5;28;01melse[39;00m:
[32m   6210[39m     keyarr, indexer, new_indexer = [38;5;28mself[39m._reindex_non_unique(keyarr)
[32m-> [39m[32m6212[39m [38;5;28;43mself[39;49m[43m.[49m[43m_raise_if_missing[49m[43m([49m[43mkeyarr[49m[43m,[49m[43m [49m[43mindexer[49m[43m,[49m[43m [49m[43maxis_name[49m[43m)[49m
[32m   6214[39m keyarr = [38;5;28mself[39m.take(indexer)
[32m   6215[39m [38;5;28;01mif[39;00m [38;5;28misinstance[39m(key, Index):
[32m   6216[39m     [38;5;66;03m# GH 42790 - Preserve name from an Index[39;00m

[36mFile [39m[32m~/opt/anaconda3/envs/jupyter-book/lib/python3.13/site-packages/pandas/core/indexes/base.py:6264[39m, in [36mIndex._raise_if_missing[39m[34m(self, key, indexer, axis_name)[39m
[32m   6261[39m     [38;5;28;01mraise[39;00m [38;5;167;01mKeyError[39;00m([33mf[39m[33m"[39m[33mNone of [[39m[38;5;132;01m{[39;00mkey[38;5;132;01m}[39;00m[33m] are in the [[39m[38;5;132;01m{[39;00maxis_name[38;5;132;01m}[39;00m[33m][39m[33m"[39m)
[32m   6263[39m not_found = [38;5;28mlist[39m(ensure_index(key)[missing_mask.nonzero()[[32m0[39m]].unique())
[32m-> [39m[32m6264[39m [38;5;28;01mraise[39;00m [38;5;167;01mKeyError[39;00m([33mf[39m[33m"[39m[38;5;132;01m{[39;00mnot_found[38;5;132;01m}[39;00m[33m not in index[39m[33m"[39m)

[31mKeyError[39m: "['Name'] not in index"

